Workbook
Name SegmentaçãodeDados_Plano: #N/A

Sheet Assets
B2: Paleta de cores | H2: Ícones
B4: #77bb44 | C4: Xbox Verde Claro
B5: #107c10 | C5: Xbox Verde Escuro
B6: #D0CECE | C6: Cinza
B7: #161616 | C7: Preto
B11: Logos

Sheet Bases
A1: ID de Assinatura do Usuário | B1: Nome | C1: Plano | D1: Data de Início | E1: Renovação Automática | F1: Preço de Assiatura | G1: Cupom de Desconto | H1: Valor Final
A2: 5670 | B2: Ana Silva | C2: Ultimate | D2: 45704 | E2: Sim | F2: =IF(C2="Ultimate", 119.9, IF(C2="Premium", 59.9)) -> 119.9 | G2: =IF(AND(C2="Ultimate",E2="Sim"),20,IF(AND(C2="Ultimate",E2="Não"),5,IF(AND(C2="Premium",E2="Sim"),10,IF(AND(C2="Premium",E2="Não"),0)))) -> 20 | H2: =SUM(F2-G2) -> 99.9
A3: 5671 | B3: João Santos | C3: Premium | D3: 45966 | E3: Não | F3: =IF(C3="Ultimate", 119.9, IF(C3="Premium", 59.9)) -> 59.9 | G3: =IF(AND(C3="Ultimate",E3="Sim"),20,IF(AND(C3="Ultimate",E3="Não"),5,IF(AND(C3="Premium",E3="Sim"),10,IF(AND(C3="Premium",E3="Não"),0)))) -> 0 | H3: =SUM(F3-G3) -> 59.9
A4: 5672 | B4: Maria Oliveira | C4: Premium | D4: 45740 | E4: Sim | F4: =IF(C4="Ultimate", 119.9, IF(C4="Premium", 59.9)) -> 59.9 | G4: =IF(AND(C4="Ultimate",E4="Sim"),20,IF(AND(C4="Ultimate",E4="Não"),5,IF(AND(C4="Premium",E4="Sim"),10,IF(AND(C4="Premium",E4="Não"),0)))) -> 10 | H4: =SUM(F4-G4) -> 49.9
A5: 5673 | B5: Pedro Costa | C5: Ultimate | D5: 45847 | E5: Não | F5: =IF(C5="Ultimate", 119.9, IF(C5="Premium", 59.9)) -> 119.9 | G5: =IF(AND(C5="Ultimate",E5="Sim"),20,IF(AND(C5="Ultimate",E5="Não"),5,IF(AND(C5="Premium",E5="Sim"),10,IF(AND(C5="Premium",E5="Não"),0)))) -> 5 | H5: =SUM(F5-G5) -> 114.9
A6: 5674 | B6: Lucas Pereira | C6: Premium | D6: 45759 | E6: Sim | F6: =IF(C6="Ultimate", 119.9, IF(C6="Premium", 59.9)) -> 59.9 | G6: =IF(AND(C6="Ultimate",E6="Sim"),20,IF(AND(C6="Ultimate",E6="Não"),5,IF(AND(C6="Premium",E6="Sim"),10,IF(AND(C6="Premium",E6="Não"),0)))) -> 10 | H6: =SUM(F6-G6) -> 49.9
A7: 5675 | B7: Mariana Rodrigues | C7: Premium | D7: 45798 | E7: Não | F7: =IF(C7="Ultimate", 119.9, IF(C7="Premium", 59.9)) -> 59.9 | G7: =IF(AND(C7="Ultimate",E7="Sim"),20,IF(AND(C7="Ultimate",E7="Não"),5,IF(AND(C7="Premium",E7="Sim"),10,IF(AND(C7="Premium",E7="Não"),0)))) -> 0 | H7: =SUM(F7-G7) -> 59.9
A8: 5676 | B8: Carlos Alves | C8: Premium | D8: 46019 | E8: Sim | F8: =IF(C8="Ultimate", 119.9, IF(C8="Premium", 59.9)) -> 59.9 | G8: =IF(AND(C8="Ultimate",E8="Sim"),20,IF(AND(C8="Ultimate",E8="Não"),5,IF(AND(C8="Premium",E8="Sim"),10,IF(AND(C8="Premium",E8="Não"),0)))) -> 10 | H8: =SUM(F8-G8) -> 49.9
A9: 5677 | B9: Fernanda Lima | C9: Ultimate | D9: 45660 | E9: Não | F9: =IF(C9="Ultimate", 119.9, IF(C9="Premium", 59.9)) -> 119.9 | G9: =IF(AND(C9="Ultimate",E9="Sim"),20,IF(AND(C9="Ultimate",E9="Não"),5,IF(AND(C9="Premium",E9="Sim"),10,IF(AND(C9="Premium",E9="Não"),0)))) -> 5 | H9: =SUM(F9-G9) -> 114.9
A10: 5678 | B10: Rafael Gomes | C10: Ultimate | D10: 45918 | E10: Sim | F10: =IF(C10="Ultimate", 119.9, IF(C10="Premium", 59.9)) -> 119.9 | G10: =IF(AND(C10="Ultimate",E10="Sim"),20,IF(AND(C10="Ultimate",E10="Não"),5,IF(AND(C10="Premium",E10="Sim"),10,IF(AND(C10="Premium",E10="Não"),0)))) -> 20 | H10: =SUM(F10-G10) -> 99.9
A11: 5679 | B11: Juliana Ribeiro | C11: Ultimate | D11: 45838 | E11: Sim | F11: =IF(C11="Ultimate", 119.9, IF(C11="Premium", 59.9)) -> 119.9 | G11: =IF(AND(C11="Ultimate",E11="Sim"),20,IF(AND(C11="Ultimate",E11="Não"),5,IF(AND(C11="Premium",E11="Sim"),10,IF(AND(C11="Premium",E11="Não"),0)))) -> 20 | H11: =SUM(F11-G11) -> 99.9
A12: 5680 | B12: Bruno Araújo | C12: Premium | D12: 45702 | E12: Sim | F12: =IF(C12="Ultimate", 119.9, IF(C12="Premium", 59.9)) -> 59.9 | G12: =IF(AND(C12="Ultimate",E12="Sim"),20,IF(AND(C12="Ultimate",E12="Não"),5,IF(AND(C12="Premium",E12="Sim"),10,IF(AND(C12="Premium",E12="Não"),0)))) -> 10 | H12: =SUM(F12-G12) -> 49.9
A13: 5681 | B13: Camila Martins | C13: Premium | D13: 45983 | E13: Sim | F13: =IF(C13="Ultimate", 119.9, IF(C13="Premium", 59.9)) -> 59.9 | G13: =IF(AND(C13="Ultimate",E13="Sim"),20,IF(AND(C13="Ultimate",E13="Não"),5,IF(AND(C13="Premium",E13="Sim"),10,IF(AND(C13="Premium",E13="Não"),0)))) -> 10 | H13: =SUM(F13-G13) -> 49.9
... A100: 5768 | B100: Rogério Paes | C100: Premium | D100: 45922 | E100: Sim | F100: =IF(C100="Ultimate", 119.9, IF(C100="Premium", 59.9)) -> 59.9 | G100: =IF(AND(C100="Ultimate",E100="Sim"),20,IF(AND(C100="Ultimate",E100="Não"),5,IF(AND(C100="Premium",E100="Sim"),10,IF(AND(C100="Premium",E100="Não"),0)))) -> 10 | H100: =SUM(F100-G100) -> 49.9

Sheet Cálculos
A1: ID de Assinatura do Usuário | B1: Preço Final | D1: Com Renovação | E1: Sem Renovação | F1: Total Final
A2: 5670 | B2: =IF(Bases!D2>DATE(2025,12,31),0, ((YEAR(DATE(2025,12,31))-YEAR(Bases!D2))*12 + (MONTH(DATE(2025,12,31))-MONTH(Bases!D2)) + 1) * Bases!H2) -> 1098.9 | D2: =SUMIF(Bases!E:E,"Sim",Cálculos!B:B) -> 28210.2 | E2: =SUMIF(Bases!E:E,"Não",Cálculos!B:B) -> 26190.6 | F2: =SUM(B:B) -> 54400.8
A3: 5671 | B3: =IF(Bases!D3>DATE(2025,12,31),0, ((YEAR(DATE(2025,12,31))-YEAR(Bases!D3))*12 + (MONTH(DATE(2025,12,31))-MONTH(Bases!D3)) + 1) * Bases!H3) -> 119.8
A4: 5672 | B4: =IF(Bases!D4>DATE(2025,12,31),0, ((YEAR(DATE(2025,12,31))-YEAR(Bases!D4))*12 + (MONTH(DATE(2025,12,31))-MONTH(Bases!D4)) + 1) * Bases!H4) -> 499
A5: 5673 | B5: =IF(Bases!D5>DATE(2025,12,31),0, ((YEAR(DATE(2025,12,31))-YEAR(Bases!D5))*12 + (MONTH(DATE(2025,12,31))-MONTH(Bases!D5)) + 1) * Bases!H5) -> 689.4
A6: 5674 | B6: =IF(Bases!D6>DATE(2025,12,31),0, ((YEAR(DATE(2025,12,31))-YEAR(Bases!D6))*12 + (MONTH(DATE(2025,12,31))-MONTH(Bases!D6)) + 1) * Bases!H6) -> 449.1
A7: 5675 | B7: =IF(Bases!D7>DATE(2025,12,31),0, ((YEAR(DATE(2025,12,31))-YEAR(Bases!D7))*12 + (MONTH(DATE(2025,12,31))-MONTH(Bases!D7)) + 1) * Bases!H7) -> 479.2 | D7: Rótulos de Linha | E7: Soma de Valor Final | H7: Rótulos de Linha | I7: Soma de Valor Final | K7: Rótulos de Linha | L7: Soma de Valor Final
A8: 5676 | B8: =IF(Bases!D8>DATE(2025,12,31),0, ((YEAR(DATE(2025,12,31))-YEAR(Bases!D8))*12 + (MONTH(DATE(2025,12,31))-MONTH(Bases!D8)) + 1) * Bases!H8) -> 49.9 | D8: Não | E8: 3491.1 | H8: Ultimate | I8: 4910.4 | J8: 4910.4 | K8: Premium | L8: 2824.7 | M8: 2824.7
A9: 5677 | B9: =IF(Bases!D9>DATE(2025,12,31),0, ((YEAR(DATE(2025,12,31))-YEAR(Bases!D9))*12 + (MONTH(DATE(2025,12,31))-MONTH(Bases!D9)) + 1) * Bases!H9) -> 1378.8 | D9: Sim | E9: 4244 | H9: Total Geral | I9: 4910.4 | K9: Total Geral | L9: 2824.7
A10: 5678 | B10: =IF(Bases!D10>DATE(2025,12,31),0, ((YEAR(DATE(2025,12,31))-YEAR(Bases!D10))*12 + (MONTH(DATE(2025,12,31))-MONTH(Bases!D10)) + 1) * Bases!H10) -> 399.6 | D10: Total Geral | E10: 7735.1
A11: 5679 | B11: =IF(Bases!D11>DATE(2025,12,31),0, ((YEAR(DATE(2025,12,31))-YEAR(Bases!D11))*12 + (MONTH(DATE(2025,12,31))-MONTH(Bases!D11)) + 1) * Bases!H11) -> 699.3
A12: 5680 | B12: =IF(Bases!D12>DATE(2025,12,31),0, ((YEAR(DATE(2025,12,31))-YEAR(Bases!D12))*12 + (MONTH(DATE(2025,12,31))-MONTH(Bases!D12)) + 1) * Bases!H12) -> 548.9
A13: 5681 | B13: =IF(Bases!D13>DATE(2025,12,31),0, ((YEAR(DATE(2025,12,31))-YEAR(Bases!D13))*12 + (MONTH(DATE(2025,12,31))-MONTH(Bases!D13)) + 1) * Bases!H13) -> 99.8 | K13: Com Renovação Automática | L13: Sem Renovação Automática | M13: Total
A14: 5682 | B14: =IF(Bases!D14>DATE(2025,12,31),0, ((YEAR(DATE(2025,12,31))-YEAR(Bases!D14))*12 + (MONTH(DATE(2025,12,31))-MONTH(Bases!D14)) + 1) * Bases!H14) -> 599 | K14: 28210.2 | L14: 26190.6 | M14: 54400.8
A15: 5683 | B15: =IF(Bases!D15>DATE(2025,12,31),0, ((YEAR(DATE(2025,12,31))-YEAR(Bases!D15))*12 + (MONTH(DATE(2025,12,31))-MONTH(Bases!D15)) + 1) * Bases!H15) -> 299.4
A16: 5684 | B16: =IF(Bases!D16>DATE(2025,12,31),0, ((YEAR(DATE(2025,12,31))-YEAR(Bases!D16))*12 + (MONTH(DATE(2025,12,31))-MONTH(Bases!D16)) + 1) * Bases!H16) -> 899.1
A17: 5685 | B17: =IF(Bases!D17>DATE(2025,12,31),0, ((YEAR(DATE(2025,12,31))-YEAR(Bases!D17))*12 + (MONTH(DATE(2025,12,31))-MONTH(Bases!D17)) + 1) * Bases!H17) -> 804.3
A18: 5686 | B18: =IF(Bases!D18>DATE(2025,12,31),0, ((YEAR(DATE(2025,12,31))-YEAR(Bases!D18))*12 + (MONTH(DATE(2025,12,31))-MONTH(Bases!D18)) + 1) * Bases!H18) -> 49.9
A19: 5687 | B19: =IF(Bases!D19>DATE(2025,12,31),0, ((YEAR(DATE(2025,12,31))-YEAR(Bases!D19))*12 + (MONTH(DATE(2025,12,31))-MONTH(Bases!D19)) + 1) * Bases!H19) -> 598.8
A20: 5688 | B20: =IF(Bases!D20>DATE(2025,12,31),0, ((YEAR(DATE(2025,12,31))-YEAR(Bases!D20))*12 + (MONTH(DATE(2025,12,31))-MONTH(Bases!D20)) + 1) * Bases!H20) -> 199.6
A21: 5689 | B21: =IF(Bases!D21>DATE(2025,12,31),0, ((YEAR(DATE(2025,12,31))-YEAR(Bases!D21))*12 + (MONTH(DATE(2025,12,31))-MONTH(Bases!D21)) + 1) * Bases!H21) -> 804.3
A22: 5690 | B22: =IF(Bases!D22>DATE(2025,12,31),0, ((YEAR(DATE(2025,12,31))-YEAR(Bases!D22))*12 + (MONTH(DATE(2025,12,31))-MONTH(Bases!D22)) + 1) * Bases!H22) -> 1263.9
A23: 5691 | B23: =IF(Bases!D23>DATE(2025,12,31),0, ((YEAR(DATE(2025,12,31))-YEAR(Bases!D23))*12 + (MONTH(DATE(2025,12,31))-MONTH(Bases!D23)) + 1) * Bases!H23) -> 229.8
A24: 5692 | B24: =IF(Bases!D24>DATE(2025,12,31),0, ((YEAR(DATE(2025,12,31))-YEAR(Bases!D24))*12 + (MONTH(DATE(2025,12,31))-MONTH(Bases!D24)) + 1) * Bases!H24) -> 999
A25: 5693 | B25: =IF(Bases!D25>DATE(2025,12,31),0, ((YEAR(DATE(2025,12,31))-YEAR(Bases!D25))*12 + (MONTH(DATE(2025,12,31))-MONTH(Bases!D25)) + 1) * Bases!H25) -> 689.4
A26: 5694 | B26: =IF(Bases!D26>DATE(2025,12,31),0, ((YEAR(DATE(2025,12,31))-YEAR(Bases!D26))*12 + (MONTH(DATE(2025,12,31))-MONTH(Bases!D26)) + 1) * Bases!H26) -> 899.1
A27: 5695 | B27: =IF(Bases!D27>DATE(2025,12,31),0, ((YEAR(DATE(2025,12,31))-YEAR(Bases!D27))*12 + (MONTH(DATE(2025,12,31))-MONTH(Bases!D27)) + 1) * Bases!H27) -> 479.2 | D27: Soma de Preço total de quem tem Auto Renovação
A28: 5696 | B28: =IF(Bases!D28>DATE(2025,12,31),0, ((YEAR(DATE(2025,12,31))-YEAR(Bases!D28))*12 + (MONTH(DATE(2025,12,31))-MONTH(Bases!D28)) + 1) * Bases!H28) -> 49.9 | D28: 28210.2
A29: 5697 | B29: =IF(Bases!D29>DATE(2025,12,31),0, ((YEAR(DATE(2025,12,31))-YEAR(Bases!D29))*12 + (MONTH(DATE(2025,12,31))-MONTH(Bases!D29)) + 1) * Bases!H29) -> 1378.8
A30: 5698 | B30: =IF(Bases!D30>DATE(2025,12,31),0, ((YEAR(DATE(2025,12,31))-YEAR(Bases!D30))*12 + (MONTH(DATE(2025,12,31))-MONTH(Bases!D30)) + 1) * Bases!H30) -> 199.6
A31: 5699 | B31: =IF(Bases!D31>DATE(2025,12,31),0, ((YEAR(DATE(2025,12,31))-YEAR(Bases!D31))*12 + (MONTH(DATE(2025,12,31))-MONTH(Bases!D31)) + 1) * Bases!H31) -> 419.3
A32: 5700 | B32: =IF(Bases!D32>DATE(2025,12,31),0, ((YEAR(DATE(2025,12,31))-YEAR(Bases!D32))*12 + (MONTH(DATE(2025,12,31))-MONTH(Bases!D32)) + 1) * Bases!H32) -> 1098.9
A33: 5701 | B33: =IF(Bases!D33>DATE(2025,12,31),0, ((YEAR(DATE(2025,12,31))-YEAR(Bases!D33))*12 + (MONTH(DATE(2025,12,31))-MONTH(Bases!D33)) + 1) * Bases!H33) -> 99.8
A34: 5702 | B34: =IF(Bases!D34>DATE(2025,12,31),0, ((YEAR(DATE(2025,12,31))-YEAR(Bases!D34))*12 + (MONTH(DATE(2025,12,31))-MONTH(Bases!D34)) + 1) * Bases!H34) -> 499
A35: 5703 | B35: =IF(Bases!D35>DATE(2025,12,31),0, ((YEAR(DATE(2025,12,31))-YEAR(Bases!D35))*12 + (MONTH(DATE(2025,12,31))-MONTH(Bases!D35)) + 1) * Bases!H35) -> 299.4
A36: 5704 | B36: =IF(Bases!D36>DATE(2025,12,31),0, ((YEAR(DATE(2025,12,31))-YEAR(Bases!D36))*12 + (MONTH(DATE(2025,12,31))-MONTH(Bases!D36)) + 1) * Bases!H36) -> 1034.1
A37: 5705 | B37: =IF(Bases!D37>DATE(2025,12,31),0, ((YEAR(DATE(2025,12,31))-YEAR(Bases!D37))*12 + (MONTH(DATE(2025,12,31))-MONTH(Bases!D37)) + 1) * Bases!H37) -> 799.2
A38: 5706 | B38: =IF(Bases!D38>DATE(2025,12,31),0, ((YEAR(DATE(2025,12,31))-YEAR(Bases!D38))*12 + (MONTH(DATE(2025,12,31))-MONTH(Bases!D38)) + 1) * Bases!H38) -> 99.9
A39: 5707 | B39: =IF(Bases!D39>DATE(2025,12,31),0, ((YEAR(DATE(2025,12,31))-YEAR(Bases!D39))*12 + (MONTH(DATE(2025,12,31))-MONTH(Bases!D39)) + 1) * Bases!H39) -> 718.8
A40: 5708 | B40: =IF(Bases!D40>DATE(2025,12,31),0, ((YEAR(DATE(2025,12,31))-YEAR(Bases!D40))*12 + (MONTH(DATE(2025,12,31))-MONTH(Bases!D40)) + 1) * Bases!H40) -> 199.6
...

Sheet Dashboard
C2: Xbox Game Pass
C3: Cálculo de assinaturas totais do ano de 2025
A6: Olá, Jonatha F.
